<?xml version="1.0"?><robot name="Ultimate Goal Example Bot"><attributes override_thnl="true" color="#808080" number="12345"><display pos="193.50 91.70 8.00" rot="0.00000 0.00000 0.00000 1.00000" /><display pos="-173.90 82.70 -4.70" rot="0.00000 -1.00000 0.00000 0.00000" /></attributes><link name="unitycomp_0"><mass value="16.93689" /></link><link name="unitycomp_1"><mass value="1.306756" /></link><link name="unitycomp_6"><mass value="1.082257" /></link><link name="unitycomp_7"><mass value="1.082257" /></link><joint name="unityjoint_0" type="revolute"><parent link="unitycomp_0" /><child link="unitycomp_6" /><axis xyz="0.0 -0.8944271909999161 -0.44721359549995804" /><origin xyz="-11.429999913941906 18.783297634584905 -15.26560767265646" /><limit lower="" upper="" /></joint><joint name="unityjoint_1" type="revolute"><parent link="unitycomp_0" /><child link="unitycomp_7" /><axis xyz="0.0 -0.894427190999916 -0.447213595499958" /><origin xyz="11.430000086058094 18.783297634584905 -15.26560767265646" /><limit lower="" upper="" /></joint><joint name="unityjoint_2" type="revolute"><parent link="unitycomp_0" /><child link="unitycomp_1" /><axis xyz="-1.0 0.0 0.0" /><origin xyz="12.000000086058094 6.523103930246794 21.595851940634173" /><limit lower="" upper="" /></joint><joint name="unityjoint_3" type="revolute"><parent link="unitycomp_0" /><child link="unitycomp_5" /><axis xyz="-1.0 0.0 0.0" /><origin xyz="21.062499692670897 6.523103930245495 16.795851940641768" /><limit lower="" upper="" /><wheel type="2:0" offset="+/-1.75" color="#5A88FF/#231F20" /></joint><joint name="unityjoint_4" type="revolute"><parent link="unitycomp_0" /><child link="unitycomp_2" /><axis xyz="-1.0 0.0 0.0" /><origin xyz="21.062499692670794 6.523103930245592 -16.804148059358226" /><limit lower="" upper="" /><wheel type="2:0" offset="+/-1.75" color="#5A88FF/#231F20" /></joint><joint name="unityjoint_5" type="revolute"><parent link="unitycomp_0" /><child link="unitycomp_4" /><axis xyz="1.0 0.0 0.0" /><origin xyz="-21.06250030733301 6.5231039302465925 16.795851940634172" /><limit lower="" upper="" /><wheel type="2:0" offset="+/-1.75" color="#5A88FF/#231F20" /></joint><joint name="unityjoint_6" type="revolute"><parent link="unitycomp_0" /><child link="unitycomp_3" /><axis xyz="1.0 0.0 0.0" /><origin xyz="-21.06250030733311 6.523103930246495 -16.80414805936583" /><limit lower="" upper="" /><wheel type="2:0" offset="+/-1.75" color="#5A88FF/#231F20" /></joint><motor index="0" name="FLDrive" brand="1" ratio="312"><override rpm="311.7552" torque="25.96628" encoder="537.6" /><powered joints="unityjoint_6 + 1" /></motor><motor index="1" name="FRDrive" brand="1" ratio="312"><override rpm="311.7552" torque="25.96628" encoder="537.6" /><powered joints="unityjoint_4 + 1" /></motor><motor index="2" name="BLDrive" brand="1" ratio="312"><override rpm="311.7552" torque="25.96628" encoder="537.6" /><powered joints="unityjoint_5 + 1" /></motor><motor index="3" name="BRDrive" brand="1" ratio="312"><override rpm="311.7552" torque="25.96628" encoder="537.6" /><powered joints="unityjoint_3 + 1" /></motor><motor index="4" name="ringCollection" brand="0" ratio="60"><override rpm="100" torque="700" encoder="1440" /><powered joints="unityjoint_2 - 1" /></motor><motor index="5" name="ringLauncher" brand="0" ratio="60"><override rpm="100" torque="700" encoder="1440" /><powered joints="unityjoint_0 - 1,unityjoint_1 + 1" /></motor><motor index="6" name="wobbleActuator" brand="0" ratio="60"><override rpm="100" torque="700" encoder="1440" /><powered joints="" /></motor><motor index="7" name="ringConveyer" brand="0" ratio="60"><override rpm="100" torque="700" encoder="1440" /><powered joints="" /></motor></robot>